Workbook

Sheet REGISTRO INCIDENCIAS
AM1: FL-THN-POS-01 Rev: 03
E2: REGISTRO DE INCIDENCIAS DE SEGURIDAD
A3: INICIO | M3: PLAN DE ACCIÓN | S3: ESCALAMIENTO | X3: NOTIFICACIÓN AL CLIENTE | AA3: RESOLUCIÓN | AG3: CIERRE DE ACCIONES
A4: Número de ticket | B4: Fecha apertura | C4: Hora apertura | D4: Tipo de Incidente | E4: Notificado por | F4: Clasificación | G4: Estado | H4: Impacto | I4: Urgencia | J4: Criticidad | K4: Prioridad | L4: Origen del Incidente | M4: Alcance | N4: Objetivos | O4: Responsable | P4: Partes intervinientes | Q4: Recursos involucrados | R4: Actividades y/o tareas a desarrollar | S4: ¿Requiere escalamiento? | T4: Nivel de escalamiento | U4: Escalado a (rol / área) | V4: Fecha y hora de escalamiento | W4: Motivo del escalamiento | X4: Fecha de notificación al cliente | Y4: Hora de notificación | Z4: Tiempo de notificación (h) | AA4: Fecha de resolución | AB4: Hora de resolución | AC4: Causa raíz | AD4: Solución aplicada | AE4: Tiempo de resolución (h) | AF4: ¿Cumplió SLA? | AG4: Fecha de Cierre | AH4: Hora cierre | AI4: Criterio de cierre | AJ4: Conformidad del usuario | AK4: Cerrado por | AL4: Lecciones Aprendidas | AM4: Responsable Resolución | AN4: Observación
A5: 3700 (Stellar Cyber) | B5: 46265 | C5: 0.31508102 | D5: Detección de archivo catalogado como PUA en host de tenant CAJAANDE | E5: Sophos | F5: Otros | G5: Cerrado | H5: Bajo | I5: Baja | J5: Baja | K5: {=IF(OR($H5="",$I5=""),"",INDEX(PARAMETROS!$C$6:$E$8,MATCH($H5,PARAMETROS!$B$6:$B$8,0),MATCH($I5,PARAMETROS!$C$5:$E$5,0)))} | L5: Host: CJPPA081 | M5: N/A | N5: N/A | O5: N/A | P5: N/A | Q5: Host: CJPPA081 User: CAJAANDE\c3412949 IP: 172.16.202.111 | R5: Realizar la eliminación manual del archivo C:\Users\mkt_sege\Downloads\CorelDRAW Graphics Suite 2022 v24.0.0.301.rar | S5: No | U5: N/A | V5: N/A | W5: N/A | X5: 46265 | Y5: 0.50416667 | Z5: =IF(OR($B5="",$X5=""),"",ROUND((($X5+$Y5)-($B5+$C5))*24,1)) | AA5: 46266 | AB5: 0.41666667 | AC5: Archivo catalogado como PUA en host de tenant CAJAANDE | AD5: Eliminación manual del archivo a través del Live Response del Sophos | AE5: =IF(OR($B5="",$AA5=""),"",ROUND((($AA5+$AB5)-($B5+$C5))*24,1)) | AF5: {=IF(OR($Z5="",$K5=""),"",IF($Z5<=INDEX(PARAMETROS!$E$25:$E$28,MATCH($K5,PARAMETROS!$A$25:$A$28,0)),"Sí","No"))} | AG5: 46266 | AH5: 0.41666667 | AI5: Eliminación de la causa de la alerta | AJ5: Conforme | AK5: Hermes Sánchez | AL5: N/A | AM5: Hermes Sánchez | AN5: N/A
A6: 15581 (Stella Cyber) | B6: 46284 | C6: 0.11458333 | D6: Caída de Sensor de Red NDR - technoma-sensor | E6: Stella Cyber | F6: Disponibilidad | G6: Cerrado | H6: Alto | I6: Alta | J6: Alta | K6: {=IF(OR($H6="",$I6=""),"",INDEX(PARAMETROS!$C$6:$E$8,MATCH($H6,PARAMETROS!$B$6:$B$8,0),MATCH($I6,PARAMETROS!$C$5:$E$5,0)))} | L6: Sensor de red: technoma-sensor | M6: N/A | N6: N/A | O6: N/A | P6: N/A | Q6: Nombre: technoma-sensor IP: 192.168.15.70 SO: Ubuntu 22.04 (QEMU) | R6: Notificar por llamada al Soc Manager. | S6: No | U6: N/A | V6: N/A | W6: N/A | X6: 46284 | Y6: 0.13055556 | Z6: =IF(OR($B6="",$X6=""),"",ROUND((($X6+$Y6)-($B6+$C6))*24,1)) | AA6: 46284 | AB6: 0.13680556 | AC6: Desconexión Temporal por Actualización de Sensor | AD6: El sensor reanudó automáticamente su conectividad y restableció el flujo normal de telemetría de red luego de 32 minutos. | AE6: =IF(OR($B6="",$AA6=""),"",ROUND((($AA6+$AB6)-($B6+$C6))*24,1)) | AF6: {=IF(OR($Z6="",$K6=""),"",IF($Z6<=INDEX(PARAMETROS!$E$25:$E$28,MATCH($K6,PARAMETROS!$A$25:$A$28,0)),"Sí","No"))} | AG6: 46284 | AH6: 0.14722222 | AI6: Sensor Conectado y Actualizado | AJ6: Conforme | AK6: Angel Insaurralde | AL6: N/A | AM6: Angel Insaurralde | AN6: N/A
A7: 568 (Cortex XDR) | B7: 46280 | C7: 0.89791667 | D7: Uso de Software No Autorizado | E7: Cortex XDR | F7: Otros | G7: Escalado | H7: Bajo | I7: Baja | J7: Baja | K7: {=IF(OR($H7="",$I7=""),"",INDEX(PARAMETROS!$C$6:$E$8,MATCH($H7,PARAMETROS!$B$6:$B$8,0),MATCH($I7,PARAMETROS!$C$5:$E$5,0)))} | L7: Cortex XDR | M7: N/A | N7: N/A | O7: N/A | P7: N/A | Q7: Host: nb-emarquez User: TECHNOMA\eduardomarquez | R7: Realizar la desinstalación del archivo C:\Users\eduardomarquez\AppData\Local\Roblox\Versions\version-c5aecda2245e4fae\RobloxPlayerBeta.exe | S7: No | U7: N/A | V7: N/A | W7: N/A | X7: 46287 | Y7: 0.64861111 | Z7: =IF(OR($B7="",$X7=""),"",ROUND((($X7+$Y7)-($B7+$C7))*24,1)) | AA7: 46287 | AB7: 0.64861111 | AC7: Instalación de software no autorizado | AD7: Notificación para la desinstalación del software no autorizado. | AE7: =IF(OR($B7="",$AA7=""),"",ROUND((($AA7+$AB7)-($B7+$C7))*24,1)) | AF7: {=IF(OR($Z7="",$K7=""),"",IF($Z7<=INDEX(PARAMETROS!$E$25:$E$28,MATCH($K7,PARAMETROS!$A$25:$A$28,0)),"Sí","No"))} | AG7: 46287 | AH7: 0.64861111 | AI7: Notificación para la desinstalación del software no autorizado. | AJ7: Conforme | AK7: Hermes Sánchez | AL7: N/A | AM7: Hermes Sánchez | AN7: N/A
A8: 114995(Oddo) | B8: 46289 | C8: 0.15277778 | D8: Caída de Sensor de Red y Agente - Sensor-Modular-CajaAnde / VMBASE8 | E8: Oddo | F8: Disponibilidad | G8: Cerrado | H8: Alto | I8: Alta | J8: Alta | K8: {=IF(OR($H8="",$I8=""),"",INDEX(PARAMETROS!$C$6:$E$8,MATCH($H8,PARAMETROS!$B$6:$B$8,0),MATCH($I8,PARAMETROS!$C$5:$E$5,0)))} | L8: Sensor de red: Sensor-Modular-CajaAnde / Agente: VMBASE8 | M8: N/A | N8: N/A | O8: N/A | P8: N/A | Q8: Sensor: Sensor-Modular-CajaAnde (ID 01f719f1094e4cfaaf2bbb6a0526400a) · Host: VMBASE8 (ID 4c735067a7f5483ca72265eb5324214c) · IP Gateway: 190.52.189.87 | R8: Enviar RFA al cliente para verificar suministro eléctrico e hipervisor de la VM del sensor, y estado del enlace de Internet y del túnel VPN (IP 190.52.189.87). | S8: No | U8: N/A | V8: N/A | W8: N/A | X8: 46289 | Y8: 0.19444444 | Z8: =IF(OR($B8="",$X8=""),"",ROUND((($X8+$Y8)-($B8+$C8))*24,1)) | AA8: 46289 | AB8: 0.3125 | AC8: Sensor y agente desconectado por corte de luz | AD8: El sensor y agente reanudaron automáticamente su conectividad y restableció el flujo normal de telemetría de red luego de 4 horas y 50 minutos. | AE8: =IF(OR($B8="",$AA8=""),"",ROUND((($AA8+$AB8)-($B8+$C8))*24,1)) | AF8: {=IF(OR($Z8="",$K8=""),"",IF($Z8<=INDEX(PARAMETROS!$E$25:$E$28,MATCH($K8,PARAMETROS!$A$25:$A$28,0)),"Sí","No"))} | AG8: 46289 | AH8: 0.3125 | AI8: Sensor conectado y enviando telemetría normal | AJ8: Conforme | AK8: Angel Insaurralde | AL8: N/A | AM8: Angel Insaurralde | AN8: N/A
A9: 118658(Odoo) 118608(Odoo) | B9: 46299 | C9: 0.125 | D9: Caída de Sensor de Red y Agente - Sensor-Modular-Caja Ande / VMBASE8 | E9: Stellar Cyber | F9: Disponibilidad | G9: Cerrado | H9: Alto | I9: Alta | J9: Alta | K9: {=IF(OR($H9="",$I9=""),"",INDEX(PARAMETROS!$C$6:$E$8,MATCH($H9,PARAMETROS!$B$6:$B$8,0),MATCH($I9,PARAMETROS!$C$5:$E$5,0)))} | L9: Sensor de red: Sensor-Modular-CajaAnde / Agente: VMBASE8 | M9: N/A | N9: N/A | O9: N/A | P9: N/A | Q9: Sensor: Sensor-Modular-CajaAnde Host: VMBASE8 IP Gateway: 190.52.189.87 | R9: Validar corte con NOC, notificar al contacto César (CAJA ANDE) a las 04:00 AM y confirmar restablecimiento a las 09:00 AM. | S9: No | U9: N/A | V9: N/A | W9: N/A | X9: 46299 | Y9: 0.16666667 | Z9: 1 | AA9: 46299 | AB9: 0.375 | AC9: Corte de fibra óptica en enlace perimetral de Caja Ande (confirmado por NOC). | AD9: Proveedor normalizó enlace de fibra a las 09:00 AM. El sensor y agente reanudaron automáticamente conectividad y telemetría luego de 6 horas. | AE9: =IF(OR($B9="",$AA9=""),"",ROUND((($AA9+$AB9)-($B9+$C9))*24,1)) | AF9: {=IF(OR($Z9="",$K9=""),"",IF($Z9<=INDEX(PARAMETROS!$E$25:$E$28,MATCH($K9,PARAMETROS!$A$25:$A$28,0)),"Sí","No"))} | AG9: 46299 | AH9: 0.375 | AI9: Sensor y agente conectados y enviando telemetría normal | AJ9: Conforme | AK9: Kevin Moraes | AL9: N/A | AM9: Kevin Moraes | AN9: N/A
A10: INC-20261008-001 | B10: 46303 | C10: 0.46736111 | D10: Conexion permitida desde IP con mala reputacion | E10: Stellar Cyber | F10: Disponibilidad | G10: Cerrado | H10: Bajo | I10: Baja | J10: Baja | K10: {=IF(OR($H10="",$I10=""),"",INDEX(PARAMETROS!$C$6:$E$8,MATCH($H10,PARAMETROS!$B$6:$B$8,0),MATCH($I10,PARAMETROS!$C$5:$E$5,0)))} | L10: 104.23.254.12 (Brasil, ASN:13335 - Cloudflare, Inc.) | M10: 190.104.178.146 (DNAT hacia servidor interno 10.11.3.196 por el puerto 443 - digitalcert.technoma.com.py) | N10: Investigar la conexión catalogada como maliciosa, determinar si hubo compromiso y documentar la justificación. | O10: N/A | P10: N/A | Q10: Firewall FortiGate, Servidor DigitalCert | R10: 1. Análisis de los logs del firewall. 2. Verificación de la reputación de la IP origen. 3. Validación del comportamiento de la sesión (tráfico transferido y estado de cierre). | S10: No | U10: N/A | V10: N/A | W10: N/A | X10: 46303 | Y10: 0.47222222 | Z10: 1 | AA10: 46303 | AB10: 0.47916667 | AC10: El sensor XDR marcó la IP 104.23.254.12 con un Threat Score de 64 (Brute_Forcer). Al pertenecer a la infraestructura de proxy reverso de Cloudflare, la IP agrupa tráfico de múltiples clientes a nivel global, heredando una mala reputación genérica en bases de datos de amenazas | AD10: Se documenta el evento como tráfico esperado a través del WAF/CDN. No se requiere bloqueo en capa 4. | AE10: 0.25 h | AF10: {=IF(OR($Z10="",$K10=""),"",IF($Z10<=INDEX(PARAMETROS!$E$25:$E$28,MATCH($K10,PARAMETROS!$A$25:$A$28,0)),"Sí","No"))} | AG10: 46303 | AH10: 0.48263889 | AI10: Falso Positivo confirmado / Comportamiento normal de insfraestructura CDN. | AJ10: Conforme | AK10: Guillermo Cabañas | AL10: N/A | AM10: Guillermo Cabañas | AN10: N/A
A11: N/A | B11: 46307 | C11: 0.51388889 | D11: Intento de conexion desde una IP con mala reputación | E11: Stellar Cyber | F11: Otros | G11: Cerrado | H11: Bajo | I11: Baja | J11: Baja | K11: {=IF(OR($H11="",$I11=""),"",INDEX(PARAMETROS!$C$6:$E$8,MATCH($H11,PARAMETROS!$B$6:$B$8,0),MATCH($I11,PARAMETROS!$C$5:$E$5,0)))} | L11: 118.145.104.37 (China, Reputación: Brute_Force, Threat Score: 98) | M11: 190.104.178.146 (DNAT hacia servidor interno 10.11.3.196 por el puerto 80 - digitalcert.technoma.com.py) | N11: Registrar y confirmar el bloqueo exitoso del tráfico malicioso. | O11: N/A | P11: N/A | Q11: Firewall FortiGate (FG-Technoma), Servidor DigitalCert | R11: 1. Verificación de logs del firewall. 2. Análisis de reputación de IP origen y Threat Score. 3. Confirmación de la aplicación de la política de bloqueo automático ("Block_Countries"). | S11: No | U11: N/A | V11: N/A | W11: N/A | X11: 46307 | Y11: 0.51388889 | Z11: 0 | AA11: 46307 | AB11: 0.51388889 | AC11: Intento de conexión entrante (HTTP/Puerto 80) desde IP proveniente de China catalogada como "Brute_Forcer". | AD11: Bloqueo automático ("deny") ejecutado en capa de red por la política del firewall "Block_Countries" (ID: 262). | AE11: 0 | AF11: Si | AG11: 46307 | AH11: 0 | AI11: Bloqueo automático confirmado en logs (craction=131072, action=deny). | AJ11: Conforme | AK11: Guillermo Cabañas | AL11: N/A | AM11: Guillermo Cabañas | AN11: N/A
A12: N/A | B12: 46308 | C12: 0.4125 | D12: Conexion permitida desde IP con mala reputacion | E12: Stellar Cyber | F12: Otros | G12: Cerrado | H12: Bajo | I12: Baja | J12: Baja | K12: P4 | L12: 16.5.0.228 (Brasil, ASN: 401661 - EMBNEX, LLC) | M12: 190.104.178.146 (DNAT hacia servidor interno 10.11.3.196 por el puerto 80 - digitalcert.technoma.com.py) | N12: Investigar la conexión catalogada como maliciosa, determinar si hubo compromiso y documentar la justificación. | O12: N/A | P12: N/A | Q12: Firewall FortiGate (FG-Technoma), Servidor DigitalCert | R12: 1. Analisis de los logs del firewall. 2. Verificación de la reputación de la ip origen (Scanner). 3. Validación del comportamiento de la sesión (tráfico transferido y estado de cierre. | S12: No | U12: N/A | V12: N/A | W12: N/A | X12: 46308 | Y12: 0.42361111 | Z12: 0 | AC12: El sensor XDR marcó la IP 16.5.0.228 con un Threat Score de 98 debido a su comportamiento y reputación previa como "Scanner" | AD12: Se documenta el evento. La sesión fue permitida por la política legítima del firewall ("Publicacion DigitalCert" ID: 219) y finalizada normalmente tras 2 segundos de duración. Al tratarse de un servicio público, la recepción de tráfico de escaneo es un comportamiento esperado en la exposición a Internet. | AE12: 0.25 | AF12: Si | AG12: 46308 | AH12: 0 | AI12: Comportamiento de escaneo sobre servicio público; cierre normal de sesión evidenciado en logs (action=close). | AJ12: Conforme | AK12: Guillermo Cabañas | AL12: N/A | AM12: Guillermo Cabañas | AN12: N/A
A13: N/A | B13: 46308 | C13: 0.32777778 | D13: Intento de conexion desde una IP con mala reputación | E13: Stellar Cyber | F13: Otros | G13: Cerrado | H13: Bajo | I13: Baja | J13: Baja | K13: P4 | L13: 167.94.146.59 (ASN: Censys, Inc., Reputación: Brute_Forcer, Threat Score: 98) | M13: 190.104.178.146 (DNAT hacia servidor interno 10.11.3.196 por el puerto 5672) | N13: Registrar y confirmar el bloqueo exitoso del tráfico no deseado. | O13: N/A | P13: N/A | Q13: Firewall FortiGate (FG-Technoma) | R13: 1. Verificación de logs del firewall. 2. Análisis de reputación de IP origen y Threat Score. 3. Confirmación de la aplicación de la política de bloqueo automático ("Block_Countries"). | S13: No | U13: N/A | V13: N/A | W13: N/A | X13: 46308 | Y13: N/A | Z13: 0 | AA13: 46308 | AB13: N/A | AC13: Intento de escaneo o conexión entrante (TCP/puerto 5672) desde la IP catalogada como "Brute_Forcer" (asociada a infraestructura de Censys). | AD13: Bloqueo automático ("deny") ejecutado en capa de red por la política del firewall "Block_Countries" (ID: 262). | AE13: 0 | AF13: Si | AG13: 46308 | AH13: 0 | AI13: Bloqueo automático confirmado en logs (craction=131072, action=deny). | AJ13: Conforme | AK13: Guillermo Cabañas | AL13: N/A | AM13: Guillermo Cabañas | AN13: N/A
A14: N/A | B14: 46308 | C14: 0.47013889 | D14: Intento de conexion desde una IP con mala reputación (Bloqueado) | E14: Stellar Cyber (FortiGate) | F14: Otros | G14: Cerrado | H14: Bajo | I14: Baja | J14: Baja | K14: P4 | L14: 45.148.10.175(Paises Bajos, ASN: Techoff Srv Limited). La IP cuenta Abuase Confidence Score de 100% (Crítico) y acumula, 7,720 reportes de abuso, principalmene por escaneo de puertos (4178 veces) y ataques de fuerza bruta. | M14: 190.104.178.146 (DNAT hacia servidor interno 10.11.3.190 por el puerto 433; puerto de destino inicial 1443) | N14: Registrar y confirmar el bloqueo exitoso de tráfico malicioso. | O14: N/A | P14: N/A | Q14: Firewall FortiGate (FG-Technoma) | R14: 1. Análisis de los logs del firewall. 2. Verificación de la reputación de la IP origen en bases de datos de inteligencia de amenazas, lo cual confirma su naturaleza maliciosa. 3. Validación de la correcta aplicación de la política de bloqueo automático ("Block_Countries"). | S14: No | U14: N/A | V14: N/A | W14: N/A | X14: 46308 | Y14: N/A | Z14: 0.47013889 | AA14: 46308 | AB14: N/A | AC14: Intento de conexión entrante (TCP/Puerto 1443) desde la IP 45.148.10.175 catalogada con Threat Score de 98 ("Brute_Forcer") y confirmada externamente como un nodo activo de ataques web y escaneo | AD14: Bloqueo automático ("deny") ejecutado en capa de red por la política del firewall "Block_Countries" (ID: 262). | AE14: 0 | AF14: Si | AG14: 46308 | AH14: 0 | AI14: Bloqueo automático confirmado en logs (craction=131072, action=deny). | AJ14: Conforme | AK14: Guillermo Cabañas | AL14: N/A | AM14: Guillermo Cabañas | AN14: N/A
A15: N/A | B15: 46308 | C15: 0.51180556 | D15: Intento de conexion desde una IP con mala reputación (Bloqueado) | E15: Stellar Cyber (FortiGate) | F15: Otros | G15: Cerrado | H15: Bajo | I15: Baja | J15: Baja | K15: P4 | L15: 5.61.209.106 (Paises Bajos, ASN: Amarutu Technology Ltd). La IP cuenta con un Abuse Confidence Score de 100% (Crítico) y acumula 3,880 reportes de abuso, destacando el escaneo de puertos y los ataques a aplicaciones web. | M15: 190.104.178.146 (DNAT hacia servidor interno 10.11.3.196 por el puerto 80) | N15: Registrar y confirmar el bloqueo exitoso de tráfico malicioso. | O15: N/A | P15: N/A | Q15: Firewall FortiGate (FG-Technoma) | R15: 1. Análisis de los logs del firewall. 2. Verificación de la reputación de la IP origen en bases de datos de inteligencia de amenazas, lo cual confirma su naturaleza maliciosa. 3. Validación de la correcta aplicación de la política de bloqueo automático ("Block_Countries"). | S15: No | U15: N/A | V15: N/A | W15: N/A | X15: 46308 | Y15: N/A | Z15: 0.51736111 | AA15: 46308 | AC15: Intento de conexión entrante (HTTP/Puerto 80) desde la IP 5.61.209.106 catalogada como "maliciosa" en los logs y confirmada externamente como un nodo muy activo con 2942 reportes de escaneo de puertos y 893 reportes de ataques a aplicaciones web. | AD15: Bloqueo automático ("deny") ejecutado en capa de red por la política del firewall "Block_Countries" (ID: 262). | AE15: 0 | AF15: Si | AG15: 46308 | AH15: 0.51875 | AI15: Bloqueo automático confirmado en logs (craction=131072, action=deny). | AJ15: Conforme | AK15: Guillermo Cabañas | AL15: N/A | AM15: Guillermo Cabañas | AN15: El tráfico fue denegado efectivamente por la política de bloqueo. No hubo transferencia de bytes (totalbytes: 0) hacia la red LAN interna. La evidencia externa consolida la peligrosidad de la IP asociada al ISP Amarutu Technology Ltd y al dominio koddos.net, confirmando que no existe riesgo de compromiso.
A16: THN-SOC-102 | B16: 46309 | C16: 0.57638889 | D16: Intento de Acceso con Cuenta Desvinculada y Credenciales en Texto Claro | E16: Stellar Cyber | F16: Compromiso de la información | G16: Cerrado | H16: Bajo | I16: Media | J16: Baja | K16: =IF(OR($H16="",$I16=""),"",INDEX(PARAMETROS!$C$6:$E$8,MATCH($H16,PARAMETROS!$B$6:$B$8,0),MATCH($I16,PARAMETROS!$C$5:$E$5,0))) | L16: 192.168.15.27 (Servidor Zabbix) / LDAP Simple Bind | M16: Dominio Active Directory technoma. local / OU Usuarios datos de baja | N16: N/A | O16: Kevin Moraes | P16: SOC Technoma, NOC Technoma | Q16: 192.168.15.27, 10.11.1.1, Cuenta AD: Mario Flores | R16: Detección de intentos de autenticación de usuario desvinculado por puerto 389. Emisión de RFA a Infraestructura para auditar origen del login. Migrar autenticacion a LDAPS puerto 636 | S16: Sí | T16: N2 - Analista de seguridad (L2_Queue) | U16: NOC | V16: 46309.595 | W16: Verificación de origen de autenticación de usuario desvinculado | X16: 46309 | Y16: 0.59513889 | Z16: =IF(OR($B16="",$X16=""),"",ROUND((($X16+$Y16)-($B16+$C16))*24,1)) | AA16: 46310 | AB16: 0.41388889 | AC16: Uso de LDAP no cifrado (puerto 389) en Zabbix e intentos de autenticación de usuario desvinculado (Mario Flores) con contraseña por defecto. | AD16: Emisión de RFA solicitando verficiacion de origen de las peticiones | AE16: =IF(OR($B16="",$AA16=""),"",ROUND((($AA16+$AB16)-($B16+$C16))*24,1)) | AF16: =IF(OR($Z16="",$K16=""),"",IF($Z16<=INDEX(PARAMETROS!$E$25:$E$28,MATCH($K16,PARAMETROS!$A$25:$A$28,0)),"Sí","No")) | AG16: 46310 | AH16: 09:56:00 | AI16: Se modificó la configuración en ambas instancias (archivos de config y DNS) cambiando el protocolo de ldap:// a ldaps:// (tráfico cifrado/puerto 636) y actualizando el Bind DN a zbx-ldaps. Se procedió a la eliminación de la cuenta local del usuario Mario Flores en ambas instancias de Zabbix. | AJ16: Conforme | AK16: Kevin Moraes | AL16: 1) Fortalecer el procedimiento de offboarding entre RRHH y TI, asegurando que la desvinculación en Active Directory incluya la purga inmediata de cuentas locales en plataformas de gestión (Zabbix). 2) Establecer como línea base de seguridad la prohibición de LDAP simple (puerto 389) en favor de LDAPS cifrado (puerto 636) para toda integración de autenticación en la infraestructura interna. | AM16: Kevin Moraes | AN16: Incidente cerrado satisfactoriamente. El NOC ejecutó las recomendaciones técnicas del RFA del SOC: migración a LDAPS (puerto 636) con Bind DN zbx-ldaps y eliminación de la cuenta huérfana en ambas instancias de Zabbix. Telemetría de red normalizada sin nuevos eventos residuales.
K17: {=IF(OR($H17="",$I17=""),"",INDEX(PARAMETROS!$C$6:$E$8,MATCH($H17,PARAMETROS!$B$6:$B$8,0),MATCH($I17,PARAMETROS!$C$5:$E$5,0)))} | AF17: {=IF(OR($Z17="",$K17=""),"",IF($Z17<=INDEX(PARAMETROS!$E$25:$E$28,MATCH($K17,PARAMETROS!$A$25:$A$28,0)),"Sí","No"))}
K18: {=IF(OR($H18="",$I18=""),"",INDEX(PARAMETROS!$C$6:$E$8,MATCH($H18,PARAMETROS!$B$6:$B$8,0),MATCH($I18,PARAMETROS!$C$5:$E$5,0)))} | AF18: {=IF(OR($Z18="",$K18=""),"",IF($Z18<=INDEX(PARAMETROS!$E$25:$E$28,MATCH($K18,PARAMETROS!$A$25:$A$28,0)),"Sí","No"))}
K19: {=IF(OR($H19="",$I19=""),"",INDEX(PARAMETROS!$C$6:$E$8,MATCH($H19,PARAMETROS!$B$6:$B$8,0),MATCH($I19,PARAMETROS!$C$5:$E$5,0)))} | AF19: {=IF(OR($Z19="",$K19=""),"",IF($Z19<=INDEX(PARAMETROS!$E$25:$E$28,MATCH($K19,PARAMETROS!$A$25:$A$28,0)),"Sí","No"))}
K20: {=IF(OR($H20="",$I20=""),"",INDEX(PARAMETROS!$C$6:$E$8,MATCH($H20,PARAMETROS!$B$6:$B$8,0),MATCH($I20,PARAMETROS!$C$5:$E$5,0)))} | AF20: {=IF(OR($Z20="",$K20=""),"",IF($Z20<=INDEX(PARAMETROS!$E$25:$E$28,MATCH($K20,PARAMETROS!$A$25:$A$28,0)),"Sí","No"))}
K21: {=IF(OR($H21="",$I21=""),"",INDEX(PARAMETROS!$C$6:$E$8,MATCH($H21,PARAMETROS!$B$6:$B$8,0),MATCH($I21,PARAMETROS!$C$5:$E$5,0)))} | AF21: {=IF(OR($Z21="",$K21=""),"",IF($Z21<=INDEX(PARAMETROS!$E$25:$E$28,MATCH($K21,PARAMETROS!$A$25:$A$28,0)),"Sí","No"))}
K22: {=IF(OR($H22="",$I22=""),"",INDEX(PARAMETROS!$C$6:$E$8,MATCH($H22,PARAMETROS!$B$6:$B$8,0),MATCH($I22,PARAMETROS!$C$5:$E$5,0)))} | AF22: {=IF(OR($Z22="",$K22=""),"",IF($Z22<=INDEX(PARAMETROS!$E$25:$E$28,MATCH($K22,PARAMETROS!$A$25:$A$28,0)),"Sí","No"))}
K23: {=IF(OR($H23="",$I23=""),"",INDEX(PARAMETROS!$C$6:$E$8,MATCH($H23,PARAMETROS!$B$6:$B$8,0),MATCH($I23,PARAMETROS!$C$5:$E$5,0)))} | AF23: {=IF(OR($Z23="",$K23=""),"",IF($Z23<=INDEX(PARAMETROS!$E$25:$E$28,MATCH($K23,PARAMETROS!$A$25:$A$28,0)),"Sí","No"))}
K24: {=IF(OR($H24="",$I24=""),"",INDEX(PARAMETROS!$C$6:$E$8,MATCH($H24,PARAMETROS!$B$6:$B$8,0),MATCH($I24,PARAMETROS!$C$5:$E$5,0)))} | AF24: {=IF(OR($Z24="",$K24=""),"",IF($Z24<=INDEX(PARAMETROS!$E$25:$E$28,MATCH($K24,PARAMETROS!$A$25:$A$28,0)),"Sí","No"))}

Sheet PARAMETROS
A3: 1. Matriz de priorización (Impacto x Urgencia)
B5: Impacto \ Urgencia | C5: Alta | D5: Media | E5: Baja
B6: Alto | C6: P1 | D6: P2 | E6: P3
B7: Medio | C7: P2 | D7: P3 | E7: P4
B8: Bajo | C8: P3 | D8: P4 | E8: P4
B10: 1.1 Criterios de Impacto (afectación al servicio y al negocio)
B11: Nivel | C11: Descripción / criterio de aplicación
B12: Alto | C12: Afecta a toda la organización o a un servicio crítico: interrupción total del servicio, pérdida, exposición o alteración de información confidencial, o incumplimiento legal, regulatorio o contractual.
B13: Medio | C13: Afecta a un área, proceso o grupo de usuarios: degradación o interrupción parcial del servicio con solución alternativa disponible y sin pérdida confirmada de información.
B14: Bajo | C14: Afecta a un usuario o a un servicio no crítico: sin pérdida de información, sin incumplimiento y sin efecto apreciable en la operación del negocio.
B16: 1.2 Criterios de Urgencia (rapidez con que debe atenderse)
B17: Nivel | C17: Descripción / criterio de aplicación
B18: Alta | C18: Requiere atención inmediata: el incidente está activo o en propagación, no existe solución alternativa y el daño crece con el tiempo.
B19: Media | C19: Requiere atención dentro de la jornada laboral: existe solución alternativa temporal y el daño no aumenta de forma acelerada.
B20: Baja | C20: Puede atenderse según programación: incidente contenido o ya finalizado, sin riesgo de propagación ni de aumento del daño.
A22: 2. Acuerdos de nivel de servicio (SLA) por prioridad
A24: Prioridad | B24: Severidad (rango Stellar Cyber) | C24: Triaje / disposición inicial | D24: Acuse de recibo (h) | E24: Notificación inicial al cliente (h) | F24: Canal primario de notificación | G24: Frecuencia de actualización
A25: P1 | B25: Crítica (90 - 100) | C25: 15 min desde la asignación del caso | D25: 0.33 | E25: 1 | F25: Teléfono (notificación inicial) + Portal del Cliente (RFA); correo de resumen a la gerencia de TI | G25: Cada hora hasta la contención
A26: P2 | B26: Alta / Mayor (75 - 89) | C26: 15 min desde la asignación del caso | D26: 2 | E26: 4 | F26: Portal del Cliente (RFA); correo electrónico de notificación | G26: Cada 4 horas hasta la contención
A27: P3 | B27: Media / Menor (41 - 74) | C27: Triaje dentro del turno de detección | D27: 8 | E27: 24 | F27: Portal del Cliente (RFA) | G27: Actualizaciones según sea necesario
A28: P4 | B28: Baja / Informativa (< 40) | C28: Gestión rutinaria dentro del turno de detección | D28: 168 | E28: 168 | F28: Portal del Cliente (registro del caso, sin RFA obligatoria) | G28: Reporte en el informe periódico al cliente
A29: Nota: los tiempos corresponden al acuse de recibo (SLO interno) y a la notificación inicial al cliente. P3 en horas hábiles; P4 = mejor esfuerzo / revisión semanal (168 h). Fuente: TB-THN-POS-01 Rev. 01 y Plan Estratégico y Operativo del Servicio SOCaaS.
A30: 3. Listas de validación (desplegables del registro)
A31: Estado | B31: Impacto | C31: Urgencia | D31: Clasificación | E31: Nivel de escalamiento | F31: Sí / No | G31: Conformidad del usuario
A32: Nuevo | B32: Alto | C32: Alta | D32: Obtención de información | E32: N1 - Mesa de servicio SOC (L1) | F32: Sí | G32: Conforme
A33: En investigación | B33: Medio | C33: Media | D33: Intento de intrusión | E33: N2 - Analista de seguridad (L2_Queue) | F33: No | G33: No conforme
A34: En análisis | B34: Bajo | C34: Baja | D34: Fraude | E34: N3 - Proveedor / Externo | G34: Pendiente
A35: En respuesta | D35: Contenido dañino
A36: Escalado | D36: Intrusión
A37: Resuelto | D37: Compromiso de la información
A38: Cerrado | D38: Disponibilidad
A39: Cancelado | D39: Vulnerable
D40: APT
D41: Otros
A43: 4. Correspondencia de la clasificación con el XDR Kill Chain y los playbooks operativos
B44: Clasificación | C44: Etapa del XDR Kill Chain | E44: Playbook aplicable
B45: Obtención de información | C45: Intentos Iniciales | E45: SC-PB-004 Reconocimiento y escaneo de red
B46: Intento de intrusión | C46: Intentos Iniciales | E46: SC-PB-001 Compromiso de credenciales (fuerza bruta / password spraying)
B47: Fraude | C47: Intentos Iniciales | E47: SC-PB-003 Actividad de phishing y posible exfiltración de datos
B48: Contenido dañino | C48: Persistencia | E48: SC-PB-002 Infección por malware / ransomware
...
